Workbook
Name __bookmark_1: #REF!
Name __Qtr4: #REF!
Name _aud98: #REF!
Name _bdm.04E336EBC3C344EB89DEFF28F82B1451.edm: #REF!
Name _bdm.17d36935db5d439cabce9c21cdd9bd39.edm: #REF!
Name _bdm.3202C8268A64487D9AE4035F30D271B6.edm: #REF!
Name _bdm.3c099f4a438144519ee34e83d7795e1e.edm: #REF!
Name _bdm.991A663BE1BA4CE6916986AE15E5C2FE.edm: #REF!
Name _bdm.D6F5CF6F8045429480DDCE6E0FB4CF8A.edm: #REF!
Name _bdm.e804dc798379461fa121860e9b194de2.edm: #REF!
Name _bdm.FA206C7EF05344A1ADB2599D6DDD41D6.edm: #REF!
Name _bdm.fe3608643574427ca90d2121c365c41f.edm: #REF!
Name _ex1: #REF!
Name _nt97: #REF!
Name _nt98: #REF!
Name _org_H_per_pot_others: #REF!
Name _php97: #REF!
Name _php98: #REF!
Name _rm97: #REF!
Name _rm98: #REF!
Name _sg1: #REF!
Name _sgd97: #REF!
Name _sgd98: #REF!
Name a: #N/A
Name AAAA: #N/A
Name ADBeg: #REF!
Name ADCurr: #REF!
Name ADEnd: #REF!
Name ADPrior: #REF!
Name allchanges1: #REF!
Name allchanges2: #REF!
Name alloc: #REF!
Name asdfdf: #REF!
Name ASSIGNED_STATES: #REF!
Name Beg_Bal: #REF!
Name Beginning_Balance: -FV(Interest_Rate/12,#REF!-1,-#REF!,Loan_Amount)
Name blank: #N/A
Name Bracket_0: #REF!
Name Bracket_1: #REF!
Name Bracket_2: #REF!
Name Bracket_3: #REF!
Name Bracket_4: #REF!
Name Bracket_5: #REF!
Name Bracket_6: #REF!
Name Bracket_7: #REF!
Name Bracket_8: #REF!
Name BS: #REF!
Name BSDate: #REF!
Name CapCase: #REF!
Name CapContCurr: #REF!
Name CapContPrior: #REF!
Name Case: #REF!
Name cash: #REF!
Name CASH_PRICE: #REF!
Name cash2: #REF!
Name CashBeg: #REF!
Name CashEnd: #REF!
Name Circ: #REF!
Name CIRCABBA: #REF!
Name CircAcq4: #REF!

Sheet I. Cover Page
B5: Opus Water, Inc
B7: LP Reporting & Valuation
B9: 46203

Sheet II. Attribution Summary
B1: ='I. Cover Page'!B5
B2: Returns Attribution Summary
B3: ='I. Cover Page'!B9 | H3: $USD
B5: Summary page
B6: Valuation Method: | D6: - Based on Average EV/EBITDA Multiple
D7: -Public comparables Discounted by 25%
B10: Comps: | D10: - No new Public Comps
D11: - No new M&A
J12: Current | L12: Prior
B13: Valuation Impacts: | D13: ='III. Valuation Summary'!F37 | E13: - Due to decrease in Multiple from 13.38x EV/Adj. EBITDA in Q4'25 to 13.30x EV/Adj. EBITDA in Q1'26 | J13: ='III. Valuation Summary'!F9 | L13: ='III. Valuation Summary'!H9
D14: ='III. Valuation Summary'!F38 | E14: - Due to decrease in TTM Adj. EBITDA from $3,112,034 in Q4'25 to $1,952,037 in Q1'26 | J14: ='III. Valuation Summary'!F10 | L14: ='III. Valuation Summary'!H10
D15: ='III. Valuation Summary'!F39 | E15: - Due to decrease in Net Cash from $1,375,759 in Q4'25 to $422,160 in Q1'26 | J15: ='III. Valuation Summary'!F13-'III. Valuation Summary'!F14 | L15: ='III. Valuation Summary'!H13-'III. Valuation Summary'!H14
D16: ='III. Valuation Summary'!$F$41 | E16: - Due to increase in ownership from 91.1% in Q4'25 to 93.7% in Q1'26 | J16: ='III. Valuation Summary'!$F$29 | L16: ='III. Valuation Summary'!$H$29
C17: Total | D17: =SUM(D13:D16)
B18: Recommendation Adj:
B19: - N/A
B25: Check | D25: =D17-'III. Valuation Summary'!F43

Sheet III. Valuation Summary
B1: ='I. Cover Page'!B5
B2: Valuation Summary
B3: ='I. Cover Page'!B9 | L3: $USD
B6: Valuation Methodology | D6: EV/EBITDA | F6: Current Period | H6: Prior Period | K6: Prior Year
B8: Company | F8: 46203 | H8: 46112 | I8: Variance | K8: 45838 | L8: Variance
B9: EV/Adj. EBITDA (A) | F9: ='V. Comparables'!$D$39 | H9: ='V. Comparables'!J39 | I9: =IFERROR(F9-H9,"n.a.") | K9: 12.360832 | L9: =IFERROR(F9-K9,"n.a.")
B10: TTM Adj. EBITDA (B) | F10: ='Pro Forma Financials (Q2)'!D38 | H10: ='Pro Forma Financials (Q1)'!D38 | I10: =IFERROR(F10-H10,"n.a.") | K10: 2563239 | L10: =IFERROR(F10-K10,"n.a.")
B12: Implied Enterprise Value (A*B) | F12: =IFERROR(F9*F10,"n.a.") | H12: =IFERROR(H9*H10,"n.a.") | I12: =IFERROR(F12-H12,"n.a.") | K12: =IFERROR(K9*K10,"n.a.") | L12: =IFERROR(F12-K12,"n.a.")
B13: Cash | F13: ='Pro Forma Financials (Q2)'!W45 | H13: ='Pro Forma Financials (Q1)'!T45 | I13: =IFERROR(F13-H13,"n.a.") | K13: 136466.6 | L13: =IFERROR(F13-K13,"n.a.")
B14: Debt | F14: ='Pro Forma Financials (Q2)'!W49 | H14: ='Financial Summary'!$I$60 | I14: =IFERROR(F14-H14,"n.a.") | K14: 0 | L14: =IFERROR(F14-K14,"n.a.")
B15: Equity Value | F15: =IFERROR(F12+F13-F14,"n.a.") | H15: =IFERROR(H12+H13-H14,"n.a.") | I15: =IFERROR(F15-H15,"n.a.") | K15: =IFERROR(K12+K13-K14,"n.a.") | L15: =IFERROR(F15-K15,"n.a.")
B18: XPV Ownership
B19: Investment Cost
B20: Common Shares | F20: ='Cap Table (Jun 2026)'!D10 | H20: ='Cap Table (Dec 2025)'!D10 | I20: =F20-H20 | K20: 12500000 | L20: =IFERROR(F20-K20,"n.a.")
B21: XPV Cost | F21: =SUM(F20:F20) | H21: =SUM(H20:H20) | I21: =F21-H21 | K21: =SUM(K20:K20) | L21: =IFERROR(F21-K21,"n.a.")
B23: Investment Value
B24: Common Shares | F24: ='Cap Table (Jun 2026)'!J35 | H24: ='Cap Table (Dec 2025)'!J35 | I24: =F24-H24 | K24: 29041296 | L24: =IFERROR(F24-K24,"n.a.")
B25: XPV Value | F25: =SUM(F24:F24) | H25: =SUM(H24:H24) | I25: =F25-H25 | K25: =SUM(K24:K24) | L25: =IFERROR(F25-K25,"n.a.")
B26: XPV Investment Multiple | F26: =F25/F21 | H26: =H25/H21 | I26: =F26-H26 | K26: =K25/K21 | L26: =IFERROR(F26-K26,"n.a.")
B27: XPV IRR | F27: ='IRR Calculation (Jun 2026)'!F28 | H27: ='IRR Calculation (Dec 2025)'!F28 | K27: 0.94085392
B28: XPV Common Ownership | F28: ='Cap Table (Jun 2026)'!I10 | H28: ='Cap Table (Dec 2025)'!I10 | K28: 0.9469697
B29: XPV FD Ownership | F29: =F25/F15 | H29: =H25/H15 | K29: =K25/K15
B30: Equity Cost Basis | F30: =F21/F29 | H30: =H21/H29 | K30: =K21/K29
B31: Cash | F31: =-F13 | H31: =-H13 | K31: =-K13
B32: Debt | F32: =F14 | H32: =H14 | K32: =K14
B33: Cost Basis | F33: =SUM(F30:F32) | H33: =SUM(H30:H32) | K33: =SUM(K30:K32)
B34: Cost Basis / Adj. EBITDA | F34: =F33/F10 | H34: =H33/H10 | K34: =K33/K10
B36: Attribution Summary
B37: Impact of Multiple | F37: =((F9-H9)*F10)*F29 | H37: 0 | K37: 0
B38: Impact of EBITDA | F38: =((F10-H10)*H9)*F29 | H38: 0 | K38: 0
B39: Impact of Net Cash | F39: =((H14-H13)-(F14-F13))*F29 | H39: 0 | K39: 0
B40: Impact of FX | F40: 0 | H40: 0 | K40: 0
B41: Change in Ownership | F41: =(F29-H29)*H15 | H41: 0 | K41: 0
B42: Change in Valuation Methodology | F42: 0 | H42: 0 | K42: 0
F43: =SUM(F37:F42) | H43: =SUM(H37:H42) | K43: =SUM(K37:K42)
F44: =F43-I25 | H44: =H43-J25 | K44: =K43-M25

Sheet IV. EBITDA Adjustments
B3: XPV Portfolio Company Adjustments to EBITDA
B4: Opus Water
E6: =EOMONTH(P6,-11) | F6: =EOMONTH(E6,1) | G6: =EOMONTH(F6,1) | H6: =EOMONTH(G6,1) | I6: =EOMONTH(H6,1) | J6: =EOMONTH(I6,1) | K6: =EOMONTH(J6,1) | L6: =EOMONTH(K6,1) | M6: =EOMONTH(L6,1) | ... O6: =EOMONTH(N6,1) | P6: ='I. Cover Page'!B9 | Q6: LTM
B7: Opus Water | E7: ='Pro Forma Financials (Q1)'!I21 | F7: ='Pro Forma Financials (Q1)'!J21 | G7: ='Pro Forma Financials (Q1)'!K21 | H7: ='Pro Forma Financials (Q1)'!L21 | I7: ='Pro Forma Financials (Q1)'!M21 | J7: ='Pro Forma Financials (Q1)'!N21 | K7: ='Pro Forma Financials (Q1)'!O21 | L7: ='Pro Forma Financials (Q1)'!P21 | ... P7: ='Pro Forma Financials (Q1)'!T21 | Q7: =SUM(E7:P7)
B8: RP Adams | E8: ='Pro Forma Financials (Q1)'!I22 | F8: ='Pro Forma Financials (Q1)'!J22 | G8: ='Pro Forma Financials (Q1)'!K22 | H8: ='Pro Forma Financials (Q1)'!L22 | I8: ='Pro Forma Financials (Q1)'!M22 | J8: ='Pro Forma Financials (Q1)'!N22 | K8: ='Pro Forma Financials (Q1)'!O22 | L8: ='Pro Forma Financials (Q1)'!P22 | ... P8: ='Pro Forma Financials (Q1)'!T22 | Q8: =SUM(E8:P8)
B9: Yeary Controls | E9: ='Pro Forma Financials (Q1)'!I23 | F9: ='Pro Forma Financials (Q1)'!J23 | G9: ='Pro Forma Financials (Q1)'!K23 | H9: ='Pro Forma Financials (Q1)'!L23 | I9: ='Pro Forma Financials (Q1)'!M23 | J9: ='Pro Forma Financials (Q1)'!N23 | K9: ='Pro Forma Financials (Q1)'!O23 | L9: ='Pro Forma Financials (Q1)'!P23 | ... P9: ='Pro Forma Financials (Q1)'!T23 | Q9: =SUM(E9:P9)
B10: PF EBITDA | E10: =SUM(E7:E9) | F10: =SUM(F7:F9) | G10: =SUM(G7:G9) | H10: =SUM(H7:H9) | I10: =SUM(I7:I9) | J10: =SUM(J7:J9) | K10: =SUM(K7:K9) | L10: =SUM(L7:L9) | ... Q10: =SUM(Q7:Q9)
B12: Category 1: Recruitment
B13: Total One-Time Recruitment Expenses
C14: Recruiting Costs | E14: 0 | F14: 0 | G14: 0 | H14: 0 | I14: 0 | J14: 22481.25 | K14: 22481.25 | L14: 68106.25 | M14: 16856.25 | N14: 1856.25 | O14: 1856.25 | P14: 19500 | Q14: =SUM(E14:P14)
C15: Day Bonus & Taxes | Q15: =SUM(E15:P15)
B16: Recruitment Expenses | E16: =IF(E13>0,E13,SUM(E14:E15)) | F16: =IF(F13>0,F13,SUM(F14:F15)) | G16: =IF(G13>0,G13,SUM(G14:G15)) | H16: =IF(H13>0,H13,SUM(H14:H15)) | I16: =IF(I13>0,I13,SUM(I14:I15)) | J16: =IF(J13>0,J13,SUM(J14:J15)) | K16: =IF(K13>0,K13,SUM(K14:K15)) | L16: =IF(L13>0,L13,SUM(L14:L15)) | ... P16: =IF(P13>0,P13,SUM(P14:P15)) | Q16: =SUM(E16:P16)
B18: Category 2: XPV Related
B19: Total XPV Expenses
C20: Petra Coach | Q20: =SUM(E20:P20)
C21: Board Fees | E21: 0 | F21: 25184.25 | G21: 2205.34 | H21: 0 | I21: 13880.54 | J21: 0 | L21: 12500 | N21: 0 | O21: 25000 | Q21: =SUM(E21:P21)
B22: XPV Related Expenses | E22: =IF(E19>0,E19,SUM(E20:E21)) | F22: =IF(F19>0,F19,SUM(F20:F21)) | G22: =IF(G19>0,G19,SUM(G20:G21)) | H22: =IF(H19>0,H19,SUM(H20:H21)) | I22: =IF(I19>0,I19,SUM(I20:I21)) | J22: =IF(J19>0,J19,SUM(J20:J21)) | K22: =IF(K19>0,K19,SUM(K20:K21)) | L22: =IF(L19>0,L19,SUM(L20:L21)) | ... P22: =IF(P19>0,P19,SUM(P20:P21)) | Q22: =SUM(E22:P22)
B24: Category 3: Financing Related
B25: Total One-Time Financing Expenses
Q26: =SUM(E26:P26)
B27: Financing Related Expenses | E27: =IF(E25>0,E25,SUM(E26:E26)) | F27: =IF(F25>0,F25,SUM(F26:F26)) | G27: =IF(G25>0,G25,SUM(G26:G26)) | H27: =IF(H25>0,H25,SUM(H26:H26)) | I27: =IF(I25>0,I25,SUM(I26:I26)) | J27: =IF(J25>0,J25,SUM(J26:J26)) | K27: =IF(K25>0,K25,SUM(K26:K26)) | L27: =IF(L25>0,L25,SUM(L26:L26)) | ... P27: =IF(P25>0,P25,SUM(P26:P26)) | Q27: =SUM(E27:P27)
B29: Category 4: M&A Related
B30: Total M&A Related Items
C31: Choate Expenses | Q31: =SUM(E31:P31)
C32: Target #2 Phase 1 | Q32: =SUM(E32:P32)
C33: EY Due Diligence | Q33: =SUM(E33:P33)
C34: M&A Travel and Expenses | Q34: =SUM(E34:P34)
C35: PTI Phase 1 | Q35: =SUM(E35:P35)
C36: Target #3 Phase 1 | Q36: =SUM(E36:P36)
C37: XPV M&A Expense | E37: 8363.94 | F37: 99666.86 | G37: 18875.42 | H37: 143182.95 | I37: -24985.22 | J37: 4926.06 | K37: 2679.17 | L37: 10715.99 | M37: 168544.19 | N37: 2957.82 | O37: 7123.34 | P37: 2747.17 | Q37: =SUM(E37:P37)
C38: RP Adams Phase I | Q38: =SUM(E38:P38)
C39: Target #4 Phase I | Q39: =SUM(E39:P39)
B40: M&A Related Items | E40: =IF(E30>0,E30,SUM(E31:E39)) | F40: =IF(F30>0,F30,SUM(F31:F39)) | G40: =IF(G30>0,G30,SUM(G31:G39)) | H40: =IF(H30>0,H30,SUM(H31:H39)) | I40: =IF(I30>0,I30,SUM(I31:I39)) | J40: =IF(J30>0,J30,SUM(J31:J39)) | K40: =IF(K30>0,K30,SUM(K31:K39)) | L40: =IF(L30>0,L30,SUM(L31:L39)) | ... P40: =IF(P30>0,P30,SUM(P31:P39)) | Q40: =SUM(E40:P40)
B42: Category 5: Exit Related
B43: Total Exit Related Expenses
Q44: =SUM(E44:P44)
B45: Exit Related Expenses | E45: =IF(E43>0,E43,SUM(E44:E44)) | F45: =IF(F43>0,F43,SUM(F44:F44)) | G45: =IF(G43>0,G43,SUM(G44:G44)) | H45: =IF(H43>0,H43,SUM(H44:H44)) | I45: =IF(I43>0,I43,SUM(I44:I44)) | J45: =IF(J43>0,J43,SUM(J44:J44)) | K45: =IF(K43>0,K43,SUM(K44:K44)) | L45: =IF(L43>0,L43,SUM(L44:L44)) | ... P45: =IF(P43>0,P43,SUM(P44:P44)) | Q45: =SUM(E45:P45)
B47: Category 6: Compensation
B48: Total Non-Recurring or One-Time Compensation
C49: Consulting Expenses | E49: 26242.39 | F49: 19080 | G49: 8420 | H49: 76584.3 | I49: 59321.73 | J49: 80472 | K49: 51815 | L49: 113108.69 | M49: 90413.54 | N49: 63406.25 | O49: 80411.25 | P49: 77315.52 | Q49: =SUM(E49:P49)
...

Sheet V. Comparables
B1: ='I. Cover Page'!B5
B2: Comparables Summary
B3: ='I. Cover Page'!B9
D4: PitchBook Tags
D5: EnterpriseValueDiluted | M5: EnterpriseValueDiluted | P5: Market Cap
D6: Total Revenue | M6: EBITDA | P6: Total Revenue
B8: Public Company Comparables | D8: Current Period | G8: Prior Period | J8: Prior Period | M8: Current Period | P8: Current Period
D9: =B3 | G9: 45291 | J9: 46022 | M9: =D9 | P9: =M9
A10: Ticker | B10: Public Companies | D10: EV/EBITDA | G10: EV/EBITDA | J10: EV/EBITDA | M10: EV/S | P10: P/S | S10: Description | T10: Business Model | U10: Rationale | V10: Source
A11: NYS:EMR | B11: Emerson Electric | D11: 18.082646 | E11: =D11*(1-$C$58) | G11: 16.457665 | H11: 0 | I11: 0 | J11: 18.524149 | K11: =J11*(1-$C$58) | M11: 4.7190278 | N11: =IFERROR(M11*(1-$C$58),"na") | P11: 4.7190278 | Q11: =IFERROR(P11*(1-$C$58),"na") | T11: Manufacturer | U11: ='VI. Comparables (Description)'!E8
A12: NYS:XYL | B12: Xylem | D12: 16.855381 | E12: =D12*(1-$C$58) | G12: 29.101149 | H12: 0 | I12: 0 | J12: 19.417677 | K12: =J12*(1-$C$58) | M12: 3.2796636 | N12: =IFERROR(M12*(1-$C$58),"na") | P12: 3.2796636 | Q12: =IFERROR(P12*(1-$C$58),"na") | T12: Manufacturer | U12: ='VI. Comparables (Description)'!E9
A13: NYS:IEX | B13: IDEX | D13: 16.970012 | E13: =D13*(1-$C$58) | G13: 17.616481 | H13: 0 | I13: 0 | J13: 16.563025 | K13: =J13*(1-$C$58) | M13: 4.4345353 | N13: =IFERROR(M13*(1-$C$58),"na") | P13: 4.4345353 | Q13: =IFERROR(P13*(1-$C$58),"na") | T13: Manufacturer | U13: ='VI. Comparables (Description)'!E10
A14: NYS:GGG | B14: Graco | D14: 17.912406 | E14: =D14*(1-$C$58) | G14: 19.879331 | H14: 0 | I14: 0 | J14: 18.257487 | K14: =J14*(1-$C$58) | M14: 6.018785 | N14: =IFERROR(M14*(1-$C$58),"na") | P14: 6.018785 | Q14: =IFERROR(P14*(1-$C$58),"na") | T14: Manufacturer | U14: ='VI. Comparables (Description)'!E11
A15: NYS:CW | B15: Curtiss-Wright | D15: 32.866118 | E15: =D15*(1-$C$58) | G15: 15.368728 | H15: 0 | I15: 0 | J15: 27.972347 | K15: =J15*(1-$C$58) | M15: 7.4134338 | N15: =IFERROR(M15*(1-$C$58),"na") | P15: 7.4134338 | Q15: =IFERROR(P15*(1-$C$58),"na") | T15: Manufacturer | U15: ='VI. Comparables (Description)'!E12
A16: NYS:ITT | B16: ITT | D16: 19.526958 | E16: =D16*(1-$C$58) | G16: 14.517442 | H16: 0 | I16: 0 | J16: 19.066908 | K16: =J16*(1-$C$58) | M16: 4.1255254 | N16: =IFERROR(M16*(1-$C$58),"na") | P16: 4.1255254 | Q16: =IFERROR(P16*(1-$C$58),"na") | T16: Manufacturer | U16: ='VI. Comparables (Description)'!E13
A17: HEL:VALMT | B17: Valmet | D17: 8.5373611 | E17: =D17*(1-$C$58) | G17: 7.6968815 | H17: 0 | I17: 0 | J17: 10.394639 | K17: =J17*(1-$C$58) | M17: 1.0595724 | N17: =IFERROR(M17*(1-$C$58),"na") | P17: 1.0595724 | Q17: =IFERROR(P17*(1-$C$58),"na") | T17: Manufacturer | U17: ='VI. Comparables (Description)'!E14
A18: LON:IMI | B18: IMI | D18: 12.221549 | E18: =D18*(1-$C$58) | G18: 12.030099 | H18: 0 | I18: 0 | J18: 15.559643 | K18: =J18*(1-$C$58) | M18: 2.9052702 | N18: =IFERROR(M18*(1-$C$58),"na") | P18: 2.9052702 | Q18: =IFERROR(P18*(1-$C$58),"na") | T18: Manufacturer | U18: ='VI. Comparables (Description)'!E15
A19: NYS:WTS | B19: Watts Water Technologies | D19: 18.745936 | E19: =D19*(1-$C$58) | G19: 17.626524 | H19: 0 | I19: 0 | J19: 18.66835 | K19: =J19*(1-$C$58) | M19: 3.8837183 | N19: =IFERROR(M19*(1-$C$58),"na") | P19: 3.8837183 | Q19: =IFERROR(P19*(1-$C$58),"na") | T19: Manufacturer | U19: ='VI. Comparables (Description)'!E16
A20: NYS:FLS | B20: Flowserve | D20: 15.075696 | E20: =D20*(1-$C$58) | J20: 12.279233 | K20: =J20*(1-$C$58) | M20: 2.2028655 | N20: =IFERROR(M20*(1-$C$58),"na") | P20: 2.2028655 | Q20: =IFERROR(P20*(1-$C$58),"na") | T20: Manufacturer | U20: ='VI. Comparables (Description)'!E17
A21: LON:ROR | B21: Rotork | D21: 13.85894 | E21: =D21*(1-$C$58) | G21: 17.958951 | H21: 0 | I21: 0 | J21: 17.749766 | K21: =J21*(1-$C$58) | M21: 3.2075431 | N21: =IFERROR(M21*(1-$C$58),"na") | P21: 3.2075431 | Q21: =IFERROR(P21*(1-$C$58),"na") | T21: Manufacturer | U21: ='VI. Comparables (Description)'!E18
A22: NYS: MWA | B22: Mueller Water Products | D22: 13.534318 | E22: =D22*(1-$C$58) | G22: 13.821888 | H22: 0 | I22: 0 | J22: 12.209321 | K22: =J22*(1-$C$58) | M22: 2.9729374 | N22: =IFERROR(M22*(1-$C$58),"na") | P22: 2.9729374 | Q22: =IFERROR(P22*(1-$C$58),"na") | T22: Manufacturer | U22: ='VI. Comparables (Description)'!E19
B24: M&A | S24: Description | T24: Business Model | U24: Rationale
B25: SPX Flow (Dec 2025)1 | D25: 14.2 | J25: 14.2 | M25: N/A | P25: N/A | T25: Manufacturer | U25: ='VI. Comparables (Description)'!E21 | V25: Company Press Release | W25: https://investors.itt.com/news-releases/news-release-details/itt-acquire-spx-flow-significantly-expanding-leadership-position
B26: Leonard Valve (Dec 2025)2 | D26: 16 | J26: 16 | M26: N/A | P26: N/A | T26: Manufacturer | U26: ='VI. Comparables (Description)'!E22 | V26: PR Newswire | W26: https://www.prnewswire.com/news-releases/a-o-smith-to-acquire-leonard-valve-company-a-leader-in-water-temperature-and-flow-solutions-302612994.html
B27: Chart Industries (Jul 2025)3 | D27: 14.3 | J27: 14.3 | M27: 3.3 | P27: 3.3 | T27: Manufacturer | U27: ='VI. Comparables (Description)'!E23 | V27: Per BNP Paribas Flow Control Weekly Insight
B28: Noah Actuation (Mar 2025)4 | D28: 12.571429 | J28: 12.571429 | M28: 2.5142857 | P28: 2.5142857 | T28: Manufacturer | U28: ='VI. Comparables (Description)'!E24 | V28: Press Release | W28: https://newsnreleases.com/2025/03/11/rotork-plc-agrees-to-acquire-noah-actuation/
B29: Sundyne (Mar 2025)5 | D29: 14.5 | J29: 14.5 | M29: N/A | P29: N/A | T29: Manufacturer | U29: ='VI. Comparables (Description)'!E25 | V29: Company Press Release | W29: https://www.honeywell.com/us/en/press/2025/03/honeywell-to-acquire-sundyne-to-expand-critical-equipment-portfolio-and-aftermarket-services
B30: CIRCOR (Jun 2023)6 | D30: 13.709677 | G30: 13.709677 | H30: 0 | I30: 0 | J30: 13.709677 | M30: 2.1144279 | P30: 2.1144279 | T30: Manufacturer | U30: ='VI. Comparables (Description)'!E26 | V30: SEC Form DEF 14A | W30: https://www.sec.gov/Archives/edgar/data/1091883/000114036123034666/ny20009611x2_defm14a.htm
B31: Velan (Feb 2023)7 | D31: 11.666667 | G31: 11.666667 | H31: 0 | I31: 0 | J31: 11.666667 | M31: 0.64473684 | P31: 0.64473684 | T31: Manufacturer | U31: ='VI. Comparables (Description)'!E27 | V31: Business Wire | W31: https://www.businesswire.com/news/home/20230210005080/en/Flowserve-to-Acquire-Velan-in-an-All-cash-Transaction-Valued-at-Approximately-245-million-C329-million
B32: Habonim (Apr 2022)8 | D32: N/A | G32: 15 | H32: 0 | I32: 0 | J32: N/A | M32: 3.1818182 | P32: 3.1818182 | T32: Manufacturer | U32: ='VI. Comparables (Description)'!E28 | V32: Company Press Release | W32: https://www.itt.com/newsroom/news-releases/2022/itt-acquires-habonim-leading-provider-of-industrial-valves-and-actuators
B33: KZ Valve (May 2022)9 | D33: 15 | G33: 15.7 | H33: 0 | I33: 0 | J33: 15 | M33: 4.2857143 | P33: 4.2857143 | T33: Manufacturer | U33: ='VI. Comparables (Description)'!E29 | V33: Email per Scott Morgan (in Salesforce)
B34: Hunt Valve (Sep 2021)10 | D34: 15.7 | G34: 14 | H34: 0 | I34: 0 | J34: 15.7 | M34: 5.8 | P34: 5.8 | T34: Manufacturer | U34: ='VI. Comparables (Description)'!E30 | V34: Per BMO Precedents (Jun 27, 2024)
B35: Red Valve (Jan 2021)11 | D35: 14 | G35: 15 | H35: 0 | I35: 0 | J35: 14 | M35: 2 | P35: 2 | T35: Manufacturer | U35: ='VI. Comparables (Description)'!E31 | V35: Per BMO Precedents (Jun 27, 2024)
B36: Valmatic (Jan 2021)12 | D36: 11 | G36: 0 | H36: 0 | I36: 0 | J36: 11 | M36: 1.8 | P36: 1.8 | T36: Manufacturer | U36: ='VI. Comparables (Description)'!E32 | V36: Per BMO Precedents (Jun 27, 2024)
B38: Simple Average | D38: =AVERAGE(D25:D36,D11:D22) | G38: =AVERAGE(G30:G35,G11:G19) | J38: =IFERROR(AVERAGE(J25:J36,J11:J22),"-") | M38: =AVERAGE(M25:M36,M11:M22) | P38: =AVERAGE(P25:P36,P11:P22)
B39: Liquidity Discount (25%) on publics | D39: =AVERAGE(D25:D36,E11:E22) | G39: =AVERAGE(G30:G35,H11:H19) | J39: =IFERROR(AVERAGE(J25:J36,K11:K22),"-") | M39: =AVERAGE(M25:M36,N11:N22) | P39: =AVERAGE(P25:P36,Q11:Q22)
B41: Median | D41: =MEDIAN(D25:D36,D11:D22) | G41: =MEDIAN(G30:G35,G11:G19) | J41: =IFERROR(MEDIAN(J25:J36,J11:J22),"-") | M41: =MEDIAN(M25:M36,M11:M22) | P41: =MEDIAN(P25:P36,P11:P22)
B42: Liquidity Discount (25%) on publics | D42: =MEDIAN(D25:D36,E11:E22) | G42: =MEDIAN(G30:G35,H11:H19) | J42: =IFERROR(MEDIAN(J25:J36,K11:K22),"-") | M42: =MEDIAN(M25:M36,N11:N22) | P42: =MEDIAN(P25:P36,Q11:Q22)
B44: 1SPX Flow was acquired by ITT for $4,775M
B45: 2Leonard Valve was acquired by A.O. Smith for $470M
...

Sheet VI. Comparables (Description)
B1: Opus Water, Inc
B2: Comparables (Description)
B3: ='I. Cover Page'!$B$9
B5: Public Company Comparables - Opus Water
B7: Public Companies | C7: Description | D7: Business Model | E7: Rationale
B8: Emerson Electric | C8: Emerson Electric focuses on automation through Intelligent Devices and Software Control. It specializes in process manufacturing solutions | D8: Manufacturer | E8: Manufacturer of industrial automation products including flow control. Engineered products platform would be complementary to Emerson’s intelligent devices segment (valves, actuators, etc.) M&A identified in growth strategy
B9: Xylem | C9: Xylem is a global leader in water technology, providing solutions for water transport, treatment, testing, and efficient use across various sectors | D9: Manufacturer | E9: Pure-play water equipment and software provider. Applied Water and Water Infrastructure segment would benefit from the addition of Opus Water as extension of current portfolio which includes engineered products
B10: IDEX | C10: IDEX manufactures pumps, flow meters, valves, and fluidic systems for industrial, fire and safety, life science, and water markets | D10: Manufacturer | E10: Was one of the groups that made it to the final round in the Red Valve process. Highly acquisitive manufacturer of technical engineered products. Have made recent acquisition in the valve space. M&A strategy is focused on margins and will pay a premium if target fits in their sandbox
B11: Graco | C11: Graco manufactures equipment for managing fluids, coatings, and adhesives, specializing in hard-to-handle materials | D11: Manufacturer | E11: Manufacturer of fluid handling and control solutions for hard to handle fluids. Relatively acquisitive across all business segments. Opus Water would provide added control capabilities and specializes in corrosive fluids
B12: Curtiss-Wright | C12: Curtiss-Wright delivers engineered products like control systems, pumps, valves, and weapons handling systems to commercial, defense, and industrial markets | D12: Manufacturer | E12: Manufacturer of engineered products, ~33% of revenue derived from industrial market. M&A continues to be a top strategic priority. Acquired Dyna-Flo for their valve portfolio in FY20- (annual sales of $25M)
B13: ITT | C13: ITT is a diversified industrial company with over $3 billion in sales, offering brake pads, shock absorbers, pumps, valves, and connectors | D13: Manufacturer | E13: Manufacturer of critical engineered components, Industrial Process segment provide pumps, valves, and control systems across industrial applications, while Connect & Control Technologies provide flow control components for critical applications, both would benefit from Opus Water offerings
B14: Valmet | C14: Valmet supplies technologies, automation solutions, and services to the pulp, paper, and energy industries | D14: Manufacturer | E14: European based manufacturer of engineered products, focusing mainly on industrial applications. Owners of Neles who manufacture pinch valves (Flowrox) who compete with Onyx. Only 20% of sales in North America, an engineered products platform would provide a strong foothold for expansion into this territory
B15: IMI | C15: IMI plc is an engineering company specializing in valves and actuators for controlling air and fluid movement, serving sectors like energy, transportation, and infrastructure | D15: Manufacturer | E15: Engineered products manufacturer based in European who is highly acquisitive with 3 acquisitions in FY22. Precision and Critical Engineering divisions are complementary to Opus Water platform
B16: Watts Water Technologies | C16: Watts Water Technologies Inc. offers safety, energy efficiency, and water conservation products for residential, commercial, and industrial applications | D16: Manufacturer | E16: Water product focused manufacturer of control, treatment and safety equipment. Established line of control valves.
B17: Flowserve | C17: Flowserve Corp. manufactures flow control systems, including pumps, valves, and seals, for industries like O&G, chemical, power generation, and water management | D17: Manufacturer | E17: Specialized provider of fluid motion and control solutions, with well-established valve and actuator product lines.
B18: Rotork | C18: Rotork designs actuators and industrial components for markets like O&G, water and power, and chemicals. Its product range includes electric and fluid actuators, gearboxes, valve accessories, and pneumatic valves | D18: Manufacturer | E18: Actuator and control solutions, with a well-established presence in the water and wastewater sector. Addition of Opus Water would increase product breadth and applications
... B32: Valmatic (Jan 2021)12 | C32: Manufacturer of valves and related products, offering solutions for water treatment, power generation, and industrial applications. The company specializes in a wide range of valve types (i.e. check, ball, and butterfly valves) | D32: Manufacturer | E32: Included as relevant given Valmatic is a flow control manufacturer with overlapping portfolio
B35: 1SPX Flow was acquired by ITT for $4,775M
B36: 2Leonard Valve was acquired by A.O. Smith for $470M
B37: 3Chart Industries was acquired by Baker Hughes for $13,600M
B38: 4Noah Actuation was acquired by Rotork for £44M
B39: 5Sundyne was acquired by Honeywell for $2,160M
B40: 6Circor was acquired by KKR for $1,700M
B41: 7Velan was acquired by Flowserve for $245M
B42: 8 Habonim was acquired by ITT for $140M
B43: 9KZ Valve was acquired by IDEX for $120M
B44: 10Hunt Valve was acquired by Fairbanks Morse Defense for $360M
B45: 11Red Valve was acquired by DeZURIK for $63M
B46: 12Valmatic was acquired by AY McDonald for $120M
B53: SVANEHOJ (Nov 2023) | C53: Leading provider of customized pumps and related services particularly focusing on handling critical liquids such as LNG, LPG, methanol, and ammonia | D53: Manufacturer

Sheet PB_CACHE
A1: H4sIAAAAAAAEAO3YCVCUZRgAYJYbBI8RU8vJFRXNluVGQFCOXQ5dYGFXwJBgWX5l5Wd33YNcwsxbNHWEwTJHSxFLHc0LzzETUxHCMiUntTSdcsSbTCub7PtW3o9vxf/PSZxpHGBY+Pd49n2/9/2OxU5gZ2f3EH3h3/jLwx7dpMk1JnVhrE5XJFRa9IxRKNPkG1QGi0iYwRiMGp02KtA/MFQcgL79RcI4M2syG5goLWM2GVSsSCg357Ma9TjGotQVMdoorZllnbCvIGyulc1tY8UKxqBRsZpSVT7LxKnUhUzHe15X6vQypoRhrVcSjdqEwkCvdUSuS1tUrnG6Yr3KwBhcE1XGQoWmlPFEQWSoWDMjV2kMRjsHOwfXCoHCYjQxxeI4HcsyVsYoTmC06A3V8Fs61Yze3GQBLy8gO7vtVQqTQaOdLBIWG9U6A6vJbx+SYLE//v738cgfOVIVog4JDQgPCmb8w8Jzclw32vMEReeQF/hcIxFlP0uJHisNervObqOcnOwc3KC4m9wc0A3+ccM94Ij/+j/WFk8qFxyhNWj84/BpV7WfstqOD9DS1DVcTztceGo4FDEWpxI8JALHcZ0YMLadndFN9wyx8NHkwc81urmg+5zwTWe+24uxrK9/cTq3AO2/GvVzXNKDYEmfgP9ww/V3g1UTP+awrmswn2bFvIdWzK6h+i+rZUInBWtdKbuhmyEpExQRSUqlNENo0gnT0elVa2aUymT/UL8gfz8UcMh4hcTDEz0zJl5nKFaZjM9wwL6L6t5ZGeBp+FKktUtGF+XmxqrURag34jUMWzAgUsIY1QaNHjfV4w/2jXyUx+P32wsce7dlKLaqjy5w5niwXJ19Wq/nNXp6RLs7taI0nvRcvAy4WAuVm2vnCq8U3EFPxx3v3BPGO16m4B1vwS30dDxYrs71b9/27XnuwRh3wU10jd/Zat4A0wtdDcZmprLNlMYmKSUxHchrhJSfe6vRuzQw2l3QQpNXgeyHSVlqSkR6ajoveYWQ+umObMDMAET+QpM/AzmAL/Nw2rxMzJqm4AG3duDML9HmT2AKsYnDTEpO4h/NC8Qc3TJj21ovZxTnj7T5A5hDYDSlyR1StwnzHCEDWiwNzS5BiDxLk98DORxSJwXiCvMMMZ0XhOXdPolaTfAdbTaDKUJXPolSWURGjCy549S1ifQUUV3e6z1smPYuGtBvafUkqP4QadYEGX+kXxPzXqGXunJ2dxTpCdpsAjOYL3ubOBuJef+DkuP9BT2R2UCbx8EMQ1dCUng/jgodI552ZfP+iG9EyDtKe0fAi8QeiZHLO0w84+355QXNuOJ1tHcIvGh0NfSx6nDMoIMEbX64/WYPozdCP6fRA4BK+NZqm0D3E9P71fCxwk09kLmPNveCmQjdHpfJT+4mZOXw+Z5z9vRH5C6arAVShnPHpDA5M4a/iXYQNGin5PKcE3hWbqfRbYDKIU6yenAM52eEXLP0xm+1O30RuYUmNwOphOEkE50rzE3E3HppYP8v/uqNzI20uQHMLDDbc+eI8xNiDvVYOC/bguNcT5s1YE6E1EnZOcjq9mnep6j1TB8/RK6lyTVA5kG7W1PnavePnrDAraa9VeAVkBClWbwhriTk9UmS1ANyvF18SJMrgCyEpZ3sQFyd+T4xJ/u8cz0qDa9Ey2mzCkwWdjWyXXCEWUnIzKMXzl5MGIHICppcBqSefxm2UZcStW7c1fMb57aiZXgJrS4G1YSuvOlZyRHnIiLGxXWrri8aheJcSIvlIE6DilubiKvi84m3bkudT4sFl2ce7c0FrwwqTjYKjhBnE/JY65e/nijATTSLJmcC+S66eqW9KRUdopvRRjnPwh/vB8cnSWWSlFRlfOr4FIm7YHobig+FgjJA5/JtaDZ6KQk0xf5mRd3fePOx0IFOA7McXQ2E6nANZQnhdslLvUZ9FYk4M82ZgFsMISYkJPCHaCCm9vThK0e98Bo8lTb1YC6D8hCTozxaQiZUl7sV/I7LU0yTLJBVuCepTudKfAoRX2641vdB1VAkamixEMQVZD+DVYMr8UnEHBQWPzA1EteGoc0CMFfxnN5sEs8npGnrpPI7tcGIVNFkHpBr+OpjY75JzOUNjZqmZlyfHNqcCGYN7JEoTDn6tMtgVqFiGWOH3N8g6O4lpfpr9Tj3CW0o/veTIAvQDXynYRszg5iilI+3nPJyReZ4OlAlmJth3bDOH66apxOvqih1da+UEOSl0Z4cvG085w2bsUwhZLD+WNCfLv0QmUyTMiBr+XYKG3MsMW8ELBjkE++JzCTaTARzL6RtPW5wpR1PvD/O+9YLpXgPl9KeBLwD6GpQ+7mAC4wl4Myq6t0xZWIExtBgNICHIEBrU3J5o4k3pXLKacUiPLujaC8SvCN8hyEbM4KYfvtOeOrN+DAUTpthYB7nm982hQklZkNFVE1Wcy9khtBmMJhNvIdLm0ADCVqZNnLMRaMLQgNo1B/Qk2RzxIFyDaaYeEPu3y3YcxAfr3xpTwReM3w6sXYklzeCeGUXjoxtWoo/jb9Ged3+Af5l97n1HAAA

Sheet LP Report
H1: ='I. Cover Page'!B9
A2: Opus Water, Inc.
A6: Business Description: | F6: Investment Overview:
A7: Opus Water, Inc (“Opus” or “the Company”) is XPV’s engineered products platform, focused on acquiring manufacturers of specialty flow control products used primarily in municipal and industrial applications. Opus brings together complementary manufacturers of engineered products and related components, with an emphasis on “high wear” applications due to the necessity of application expertise to deliver reliable differentiated solutions and the opportunity for high margin aftermarket sales. Because these components are critical to the safe handling of water, and that the infrastructure or systems in which they are installed would fail without them, M&A efforts are focused on owner-operated companies that have achieved the “safe hands” status for their customers. These are also companies that can benefit from additional channels to market, synergies in procurement, and other resources that they access as part of the Opus platform. | F7: Initial Investment Date | I7: December 21, 2023
F8: Lead Partner | I8: Sam Saintonge
F9: Fully Diluted Ownership1 | I9: ='Cap Table (Dec 2025)'!K10
F10: Valuation Method | I10: Multiple of Adjusted EBITDA
F11: Total Invested Capital | I11: ='III. Valuation Summary'!F21/1000000
F12: Total Realized Proceeds | I12: 0
F13: Total Carrying Value | I13: ='III. Valuation Summary'!F25/1000000
F14: Gross Multiple of Invested Capital | I14: =IFERROR((I13+I12)/I11,"n.a.")
F15: Gross IRR | I15: ='III. Valuation Summary'!F27
A22: Financial and Strategic Update
A46: Financial Summary ($M)
C47: 2025 | D47: 2026
C48: Dec 31 | D48: Mar 31 | E48: Jun 30 | F48: Sep 30 | G48: Dec 31
A49: TTM Revenue | C49: ='Financial Summary'!M12 | D49: ='Pro Forma Financials (Q1)'!D13 | E49: ='Pro Forma Financials (Q2)'!D13
A50: TTM Adjusted EBITDA2 | C50: ='Financial Summary'!M54 | D50: ='Pro Forma Financials (Q1)'!D38 | E50: ='Pro Forma Financials (Q2)'!D38
A51: Net Cash/(Debt) | C51: ='Financial Summary'!M59 | D51: ='Pro Forma Financials (Q1)'!D46 | E51: ='Pro Forma Financials (Q2)'!D46-'Pro Forma Financials (Q2)'!D49
A52: 1 Fully diluted ownership includes management incentive programs.
A53: 2 Pro forma for one acquisition, contributing $1.54M Revenue and $0.45M Adjusted EBITDA.

Sheet Back up >>

Sheet Pro Forma Financials (Q1)
B2: Opus Water Financials
B3: Financial Summary
B4: ='I. Cover Page'!B9
B6: Financial Information Summary | U6: Notes
C8: LTM - December 2025 | D8: LTM - March 2026 | F8: 45688 | G8: =EOMONTH(F8,1) | H8: =EOMONTH(G8,1) | I8: =EOMONTH(H8,1) | J8: =EOMONTH(I8,1) | K8: =EOMONTH(J8,1) | L8: =EOMONTH(K8,1) | M8: =EOMONTH(L8,1) | N8: =EOMONTH(M8,1) | ... T8: =EOMONTH(S8,1)
C9: Jan 1 2025 - Dec 31 2025 | D9: Apr 1 2025 - Mar 31 2026 | F9: =MONTH(F8) | G9: =MONTH(G8) | H9: =MONTH(H8) | I9: =MONTH(I8) | J9: =MONTH(J8) | K9: =MONTH(K8) | L9: =MONTH(L8) | M9: =MONTH(M8) | ... T9: =MONTH(T8)
B10: Opus Revenue | C10: =SUM(F10:Q10) | D10: =SUM(I10:T10) | F10: 519951.33 | G10: 1313013.2 | H10: 2157588.1 | I10: 2083207.9 | J10: 1131620.9 | K10: 1478180.1 | L10: 1758316.5 | M10: 1413457.5 | N10: 1824735.7 | O10: 1621269.5 | P10: 1288214.6 | Q10: 2349656.2 | R10: 890161.26 | S10: 1938842.9 | T10: 1779097.4
B11: RP Adams Revenue | C11: =SUM(F11:Q11) | D11: =SUM(I11:T11) | F11: 936677.38 | G11: 641032.15
B12: Yeary Controls Revenue | C12: =SUM(F12:Q12) | D12: =SUM(I12:T12) | F12: 91371.25 | G12: 140634.75 | H12: 871204.1 | I12: 122638.2 | J12: 253544 | K12: 522588.58 | L12: 293851.7 | M12: 77550.78 | N12: 210778.38 | O12: 62134
B13: Total Revenue | C13: =SUM(C10:C12) | D13: =SUM(D10:D12) | F13: =SUM(F10:F12) | G13: =SUM(G10:G12) | H13: =SUM(H10:H12) | I13: =SUM(I10:I12) | J13: =SUM(J10:J12) | K13: =SUM(K10:K12) | L13: =SUM(L10:L12) | M13: =SUM(M10:M12) | ... T13: =SUM(T10:T12)
B15: Opus Gross Profit | C15: =SUM(F15:Q15) | D15: =SUM(I15:T15) | F15: 205074.94 | G15: 783410.93 | H15: 1284102.4 | I15: 1040699 | J15: 499492.42 | K15: 688521.9 | L15: 940795.69 | M15: 758447.05 | N15: 949347.82 | O15: 827343.84 | P15: 640531.13 | Q15: 1510721.7 | R15: 347431.45 | S15: 1182549 | T15: 971176.03
B16: RP Adams Gross Profit | C16: =SUM(F16:Q16) | D16: =SUM(I16:T16) | F16: 674224.62 | G16: 168757.32
B17: Yeary Controls Gross Profit | C17: =SUM(F17:Q17) | D17: =SUM(I17:T17) | F17: 53713.33 | G17: 65183.98 | H17: 301565.67 | I17: 62665.01 | J17: 105939.4 | K17: 158529.34 | L17: 141505.17 | M17: 4580.91 | N17: 116530.33 | O17: 32911.5
B18: Gross Profit | C18: =SUM(C15:C17) | D18: =SUM(D15:D17) | F18: =SUM(F15:F17) | G18: =SUM(G15:G17) | H18: =SUM(H15:H17) | I18: =SUM(I15:I17) | J18: =SUM(J15:J17) | K18: =SUM(K15:K17) | L18: =SUM(L15:L17) | M18: =SUM(M15:M17) | ... T18: =SUM(T15:T17)
B19: % Gross Margin | C19: =C18/C13 | D19: =D18/D13 | F19: =F18/F13 | G19: =G18/G13 | H19: =H18/H13 | I19: =I18/I13 | J19: =J18/J13 | K19: =K18/K13 | L19: =L18/L13 | M19: =M18/M13 | ... T19: =T18/T13
B21: Opus Water EBITDA | C21: =SUM(F21:Q21) | D21: =SUM(I21:T21) | F21: -40970.91 | G21: 227050.13 | H21: 232486.66 | I21: 166011.22 | J21: -419184.96 | K21: -107942.57 | L21: -376427.05 | M21: -5735.58 | N21: 43437.92 | O21: -167551.11 | P21: -208036.74 | Q21: 334935.79 | R21: -624505.52 | S21: 234015.56 | T21: 1674.3
B22: RP Adams EBITDA | C22: =SUM(F22:Q22) | D22: =SUM(I22:T22) | F22: 273530.92 | G22: 50497.71
B23: Yeary Controls EBITDA | C23: =SUM(F23:Q23) | D23: =SUM(I23:T23) | F23: 8273.51 | G23: 13262.67 | H23: 193513.63 | I23: 16377.53 | J23: 58656.07 | K23: 112282.62 | L23: 92264.19 | M23: -79211.4 | N23: 66536.39 | O23: -61523.54
B24: EBITDA | C24: =SUM(C21:C23) | D24: =SUM(D21:D23) | F24: =SUM(F21:F23) | G24: =SUM(G21:G23) | H24: =SUM(H21:H23) | I24: =SUM(I21:I23) | J24: =SUM(J21:J23) | K24: =SUM(K21:K23) | L24: =SUM(L21:L23) | M24: =SUM(M21:M23) | ... T24: =SUM(T21:T23)
B25: % EBITDA Margin | C25: =C24/C13 | D25: =D24/D13 | F25: =F24/F13 | G25: =G24/G13 | H25: =H24/H13 | I25: =I24/I13 | J25: =J24/J13 | K25: =K24/K13 | L25: =L24/L13 | M25: =M24/M13 | ... T25: =T24/T13
B27: ADJUSTMENT: Consulting | C27: =SUM(F27:Q27) | D27: =SUM(I27:T27) | F27: 21299.51 | G27: 6825 | H27: 14078 | I27: 26242.39 | J27: 19080 | K27: 8420 | L27: 76584.3 | M27: 59321.73 | N27: 80472 | O27: 51815 | P27: 113108.69 | Q27: 90413.54 | R27: 63406.25 | S27: 80411.25 | T27: 77315.52
B28: ADJUSTMENT: Recruiting Costs | C28: =SUM(F28:Q28) | D28: =SUM(I28:T28) | F28: 0 | G28: 0 | H28: 0 | I28: 0 | J28: 0 | K28: 0 | L28: 0 | M28: 0 | N28: 22481.25 | O28: 22481.25 | P28: 68106.25 | Q28: 16856.25 | R28: 1856.25 | S28: 1856.25 | T28: 19500
B29: ADJUSTMENT: Board Fees | C29: =SUM(F29:Q29) | D29: =SUM(I29:T29) | F29: 0 | G29: 25000 | H29: 0 | I29: 0 | J29: 25184.25 | K29: 2205.34 | L29: 0 | M29: 13880.54 | N29: 0 | O29: 0 | P29: 12500 | Q29: 0 | R29: 0 | S29: 25000 | T29: 0
B30: ADJUSTMENT: IT Integration | C30: =SUM(F30:Q30) | D30: =SUM(I30:T30) | F30: 0 | G30: 0 | H30: 14344 | I30: 14344 | J30: 14344 | K30: 0 | L30: 126507.79 | M30: 0 | N30: 0 | O30: 5700 | P30: 0 | Q30: 0 | R30: 15543.5 | S30: 7204.17 | T30: 8942.37
B31: ADJUSTMENT: M&A | C31: =SUM(F31:Q31) | D31: =SUM(I31:T31) | F31: -141284.86 | G31: -26791.66 | H31: 149319.43 | I31: 8363.94 | J31: 99666.86 | K31: 18875.42 | L31: 143182.95 | M31: -24985.22 | N31: 4926.06 | O31: 2679.17 | P31: 10715.99 | Q31: 168544.19 | R31: 2957.82 | S31: 7123.34 | T31: 2747.17 | U31: 1000
B32: ADJUSTMENT: Excess Temporary Labor | C32: =SUM(F32:Q32) | D32: =SUM(I32:T32) | F32: 23331.43 | G32: 43629.89 | H32: 38041.49 | I32: 50090.88 | J32: 66297.7 | K32: 45571.46 | L32: 139565.49 | M32: 100000.52 | N32: 75882.97 | O32: 112881.65 | P32: 76812.89 | Q32: 73013.31 | R32: 58784.32 | S32: 45166.42 | T32: 46457.6
B33: ADJUSTMENT: Setup Expenses | C33: =SUM(F33:Q33) | D33: =SUM(I33:T33) | F33: 528 | G33: 0 | H33: 0 | I33: 0 | J33: 0 | K33: 0 | L33: 0 | M33: -528 | N33: 0 | O33: 0 | P33: 0 | Q33: 0 | R33: 0 | S33: 0 | T33: 0
B34: ADJUSTMENT: Other | C34: =SUM(F34:Q34) | D34: =SUM(I34:T34) | F34: 2819.47 | G34: 0 | H34: 4447.32 | I34: 17072.6 | J34: 5546.84 | K34: 43398.18 | L34: 127233.28 | M34: 1980 | N34: 55734.21 | O34: 7254.6 | P34: 422.25 | Q34: -168162.86 | R34: 5385.83 | S34: 24465.7 | T34: 611.79
B35: ADJUSTMENT: Cental Office Administration Expense Removal | C35: =SUM(F35:Q35) | D35: =SUM(I35:T35) | F35: 34500
B36: ADJUSTMENT: Yeary Controls Normalized Adjustments | C36: =SUM(F36:Q36) | D36: =SUM(I36:T36) | F36: 30261.141 | G36: 38124.412 | H36: 29800.022 | I36: 30086.048 | J36: 29576.944 | K36: 30251.792 | L36: 31036.844 | M36: 35539.386 | N36: 32397.735 | O36: 60253.94
B38: Adjusted EBITDA | C38: =SUM(C27:C36)+C24 | D38: =SUM(D27:D36)+D24 | F38: =SUM(F27:F36)+F24 | G38: =SUM(G27:G36)+G24 | H38: =SUM(H27:H36)+H24 | I38: =SUM(I27:I36)+I24 | J38: =SUM(J27:J36)+J24 | K38: =SUM(K27:K36)+K24 | L38: =SUM(L27:L36)+L24 | M38: =SUM(M27:M36)+M24 | ... T38: =SUM(T27:T36)+T24
B39: % Adjusted EBITDA Margin | C39: =C38/C$13 | D39: =D38/D$13 | F39: =F38/F$13 | G39: =G38/G$13 | H39: =H38/H$13 | I39: =I38/I$13 | J39: =J38/J$13 | K39: =K38/K$13 | L39: =L38/L$13 | M39: =M38/M$13 | ... T39: =T38/T$13
B41: ADJUSTMENT: Platform Adjustments | C41: =SUM(F41:Q41) | D41: =SUM(I41:T41) | F41: 53036.48 | G41: 50668.77 | H41: 92200.04 | I41: 54296.38 | J41: 88569.44 | K41: 61413.46 | L41: 54814.8 | M41: 52844.09 | N41: 80900.92 | O41: 96291.53 | P41: 61544.94 | Q41: 64620.73 | R41: 0 | S41: 0 | T41: 0
B42: Operating Adjusted EBITDA | C42: =C38+SUM(C41:C41) | D42: =D38+SUM(D41:D41) | F42: =F38+SUM(F41:F41) | G42: =G38+SUM(G41:G41) | H42: =H38+SUM(H41:H41) | I42: =I38+SUM(I41:I41) | J42: =J38+SUM(J41:J41) | K42: =K38+SUM(K41:K41) | L42: =L38+SUM(L41:L41) | M42: =M38+SUM(M41:M41) | ... T42: =T38+SUM(T41:T41)
B43: % Operating Adjusted EBITDA Margin | C43: =C42/C$13 | D43: =D42/D$13 | F43: =F42/F$13 | G43: =G42/G$13 | H43: =H42/H$13 | I43: =I42/I$13 | J43: =J42/J$13 | K43: =K42/K$13 | L43: =L42/L$13 | M43: =M42/M$13 | ... T43: =T42/T$13
B45: Opus Cash | C45: =Q46 | D45: =T45 | H45: 136466.6 | K45: 1154703.3 | N45: 715146.47 | Q45: 1375758.7 | T45: 422159.65
B46: Cash | C46: =SUM(C45:C45) | D46: =SUM(D45:D45) | F46: =SUM(F45:F45) | G46: =SUM(G45:G45) | H46: =SUM(H45:H45) | I46: =SUM(I45:I45) | J46: =SUM(J45:J45) | K46: =SUM(K45:K45) | L46: =SUM(L45:L45) | M46: =SUM(M45:M45) | ... T46: =SUM(T45:T45)
B48: Opus Debt | C48: =K48 | D48: =T48
B49: Debt | C49: =SUM(C48:C48) | D49: =SUM(D48:D48) | F49: =SUM(F48:F48) | G49: =SUM(G48:G48) | H49: =SUM(H48:H48) | I49: =SUM(I48:I48) | J49: =SUM(J48:J48) | K49: =SUM(K48:K48) | L49: =SUM(L48:L48) | M49: =SUM(M48:M48) | ... T49: =SUM(T48:T48)
F51: =SUM(R38:T38)
...

Sheet EBITDA Adjustments 2026
B3: XPV Portfolio Company Adjustments to EBITDA
B4: Opus Water
E5: Q1 | F5: Q1 | G5: Q1 | H5: Q2 | I5: Q2 | J5: Q2 | K5: Q3 | L5: Q3 | M5: Q3 | N5: Q4 | O5: Q4 | P5: Q4
E7: 46053 | F7: =EOMONTH(E7,1) | G7: =EOMONTH(F7,1) | H7: =EOMONTH(G7,1) | I7: =EOMONTH(H7,1) | J7: =EOMONTH(I7,1) | K7: =EOMONTH(J7,1) | L7: =EOMONTH(K7,1) | M7: =EOMONTH(L7,1) | ... P7: =EOMONTH(O7,1)
B8: Opus Water | E8: ='Pro Forma Financials (Q1)'!R21 | F8: ='Pro Forma Financials (Q1)'!S21 | G8: ='Pro Forma Financials (Q1)'!T21
E9: ='Pro Forma Financials (Q1)'!R22 | F9: ='Pro Forma Financials (Q1)'!S22 | G9: ='Pro Forma Financials (Q1)'!T22
E10: ='Pro Forma Financials (Q1)'!R23 | F10: ='Pro Forma Financials (Q1)'!S23 | G10: ='Pro Forma Financials (Q1)'!T23
B11: PF EBITDA | E11: =SUM(E8:E10) | F11: =SUM(F8:F10) | G11: =SUM(G8:G10) | H11: =SUM(H8:H10) | I11: =SUM(I8:I10) | J11: =SUM(J8:J10) | K11: =SUM(K8:K10) | L11: =SUM(L8:L10) | ... P11: =SUM(P8:P10)
B13: Category 1: Recruitment
B15: Total One-Time Recruitment Expenses
A16: ADJUSTMENT: RM Executive Search | C16: Recruiting Costs | E16: 1856.25 | F16: 1856.25 | G16: 19500
B20: Recruitment Expenses | E20: =IF(E15>0,E15,SUM(E16:E19)) | F20: =IF(F15>0,F15,SUM(F16:F19)) | G20: =IF(G15>0,G15,SUM(G16:G19)) | H20: =IF(H15>0,H15,SUM(H16:H19)) | I20: =IF(I15>0,I15,SUM(I16:I19)) | J20: =IF(J15>0,J15,SUM(J16:J19)) | K20: =IF(K15>0,K15,SUM(K16:K19)) | L20: =IF(L15>0,L15,SUM(L16:L19)) | ... P20: =IF(P15>0,P15,SUM(P16:P19))
B22: Category 2: XPV Related
B24: Total XPV Expenses
A25: ADJUSTMENT: Petra Coach | C25: Petra Coach
A26: ADJUSTMENT: Board Fees | C26: Board Fees | E26: 0 | F26: 25000
A27: ADJUSTMENT: Officers Compensation | C27: Officers Compensation
B29: XPV Related Expenses | E29: =IF(E24>0,E24,SUM(E25:E28)) | F29: =IF(F24>0,F24,SUM(F25:F28)) | G29: =IF(G24>0,G24,SUM(G25:G28)) | H29: =IF(H24>0,H24,SUM(H25:H28)) | I29: =IF(I24>0,I24,SUM(I25:I28)) | J29: =IF(J24>0,J24,SUM(J25:J28)) | K29: =IF(K24>0,K24,SUM(K25:K28)) | L29: =IF(L24>0,L24,SUM(L25:L28)) | ... P29: =IF(P24>0,P24,SUM(P25:P28))
B31: Category 3: Financing Related
B33: Total One-Time Financing Expenses
B36: Financing Related Expenses | E36: =IF(E33>0,E33,SUM(E34:E35)) | F36: =IF(F33>0,F33,SUM(F34:F35)) | G36: =IF(G33>0,G33,SUM(G34:G35)) | H36: =IF(H33>0,H33,SUM(H34:H35)) | I36: =IF(I33>0,I33,SUM(I34:I35)) | J36: =IF(J33>0,J33,SUM(J34:J35)) | K36: =IF(K33>0,K33,SUM(K34:K35)) | L36: =IF(L33>0,L33,SUM(L34:L35)) | ... P36: =IF(P33>0,P33,SUM(P34:P35))
B38: Category 4: M&A Related
B40: Total M&A Related Items
C41: Choate Expenses
C42: Onyx Phase 1
C43: EY Due Diligence
A44: ADJUSTMENT: M&A related T&E | C44: M&A Travel and Expenses
C45: PTI Phase 1
C46: UniTorq Phase 1
A47: ADJUSTMENT: XPV Water Partners | C47: XPV M&A Expense | E47: 2957.82 | F47: 7123.34 | G47: 2747.17
C48: RP Adams Phase I
C49: J&S Phase I
B50: M&A Related Items | E50: =IF(E40>0,E40,SUM(E41:E49)) | F50: =IF(F40>0,F40,SUM(F41:F49)) | G50: =IF(G40>0,G40,SUM(G41:G49)) | H50: =IF(H40>0,H40,SUM(H41:H49)) | I50: =IF(I40>0,I40,SUM(I41:I49)) | J50: =IF(J40>0,J40,SUM(J41:J49)) | K50: =IF(K40>0,K40,SUM(K41:K49)) | L50: =IF(L40>0,L40,SUM(L41:L49)) | ... P50: =IF(P40>0,P40,SUM(P41:P49))
B52: Category 5: Exit Related
B54: Total Exit Related Expenses
B57: Exit Related Expenses | E57: =IF(E54>0,E54,SUM(E55:E56)) | F57: =IF(F54>0,F54,SUM(F55:F56)) | G57: =IF(G54>0,G54,SUM(G55:G56)) | H57: =IF(H54>0,H54,SUM(H55:H56)) | I57: =IF(I54>0,I54,SUM(I55:I56)) | J57: =IF(J54>0,J54,SUM(J55:J56)) | K57: =IF(K54>0,K54,SUM(K55:K56)) | L57: =IF(L54>0,L54,SUM(L55:L56)) | ... P57: =IF(P54>0,P54,SUM(P55:P56))
B59: Category 6: Compensation
B61: Total Non-Recurring or One-Time Compensation
A62: ADJUSTMENT: Marc Norseman Consulting | C62: Consulting | E62: 63406.25 | F62: 80411.25 | G62: 77315.52
A63: ADJUSTMENT: Glen Meyer Consulting
...

Sheet ToC
B1: ='I. Cover Page'!B5
B2: Table of Contents
B3: ='I. Cover Page'!B9 | J3: $USD
C8: Description | I8: Page
C9: Cap Table…………………………………………………………………………………………………………........................................................ | I9: 3
C10: Valuation Summary…………………………………………………………………………………………………………....................................... | I10: 4
C11: Comparables…………………………………………………………………………………………………………................................................... | I11: 5
C12: IRR Calcuation…………………………………………………………………………………………………………................................................ | I12: 6
C13: Attribution Summary…………………………………………………………………………………………………………………............................... | I13: 7
C14: Financial Summary…………………………………………………………………………………………………………………..................................... | I14: 8
C15: LP Report…........…………………………………………………………………………………………………………………..................................... | I15: 9

Sheet Cap Table (Mar 2026)
B2: Opus Water - Cap Table | K2: Confidential
K3: $'s in USD
B4: Illustrative Equity Value at Exit | D4: ='III. Valuation Summary'!$F$15
C6: Opus Water Cap Table
D8: Capital | E8: Common Units | F8: Incentive Units | G8: Incentive Units | H8: Total | I8: % | J8: Total | K8: %
D9: Contributed | E9: Exercise prices>>> | F9: 1 | G9: 1.6 | H9: (Basic) | I9: (Basic) | J9: (Fully Diluted) | K9: (Fully Diluted)
C10: XPV Water Fund III Limited Partnership | D10: =12500000+3787879.18 | E10: 14628022 | H10: =E10 | I10: =H10/H$19 | J10: =SUM(E10:G10) | K10: =J10/J$19
C11: 2007 Irrevocable Trust For Family of Chris M. Raftis dated March 30,2007 | D11: =600000+181818.1 | E11: 702145 | H11: =E11 | I11: =H11/H$19 | J11: =SUM(E11:G11) | K11: =J11/J$19
C12: Karl Trott | D12: =100000+30302.72 | E12: 117024 | H12: =E12 | I12: =H12/H$19 | J12: =SUM(E12:G12) | K12: =J12/J$19
C13: John DeYarman Incentive Units | F13: 233333 | G13: 466667 | I13: =H13/H$19 | J13: =SUM(E13:G13) | K13: =J13/J$19
C14: Scott Day Incentive Units | G14: 300000 | I14: =H14/H$19 | J14: =SUM(E14:G14) | K14: =J14/J$19
C15: 2007 Irrevocable Trust For Family of Chris M. Raftis dated March 30,2007 Incentive Units | G15: 110000 | I15: =H15/H$19 | J15: =SUM(E15:G15) | K15: =J15/J$19
C16: Kevin Klau | G16: 110000 | I16: =H16/H$19 | J16: =SUM(E16:G16) | K16: =J16/J$19
C17: Warren Berenis | G17: =150000+25000 | I17: =H17/H$19 | J17: =SUM(E17:G17) | K17: =J17/J$19
C18: Unallocated | G18: =1400000-SUM(F13:G17) | I18: =H18/H$19 | J18: =SUM(E18:G18) | K18: =J18/J$19
C19: Total | E19: =SUM(E10:E18) | F19: =SUM(F10:F18) | G19: =SUM(G10:G18) | H19: =SUM(H10:H18) | I19: =H19/H$19 | J19: =SUM(J10:J18) | K19: =J19/J$19
B21: EQUITY PROCEEDS
E22: Incentive Units | F22: Incentive Units | G22: Common Units | H22: Incentive Units | I22: Incentive Units
E23: =F9 | F23: =G9 | H23: =F9 | I23: =G9
C24: Equity Value | E24: =D4 | F24: =E24 | G24: =F24-E45-F45 | H24: =G24 | I24: =H24
C26: Common Units | E26: =E19 | F26: =E26 | G26: =E26 | H26: =G26 | I26: =H26
C27: Incentive Units ($1.00) | E27: =F19 | F27: =E27 | G27: =IF(E45<0,E27,0) | H27: =G27 | I27: =H27
C28: Incentive Units ($1.60) | E28: =G19 | F28: =E28 | G28: =IF(F45<0,E28,0) | H28: =G28 | I28: =H28
C30: Total Units | E30: =SUM(E26:E29) | F30: =SUM(F26:F29) | G30: =SUM(G26:G29) | H30: =SUM(H26:H29) | I30: =SUM(I26:I29)
C31: Equity Value Per Unit | E31: =E24/E30 | F31: =F24/F30 | G31: =G24/G30 | H31: =H24/H30 | I31: =I24/I30
E33: Options Exercise | G33: Common Units
E34: Incentive Units ($1.00) | F34: Incentive Units ($1.60) | G34: Common Units | H34: Incentive Units ($1.00) | I34: Incentive Units ($1.60) | J34: Proceeds
C35: XPV Water Fund III Limited Partnership | E35: =IF(H$31>F$9,-F$9*F10,0) | F35: =IF(I$31>G$9,-G$9*G10,0) | G35: =E10*G$31 | H35: =IF(E$45<0,F10*H$31,0) | I35: =IF(F$45<0,G10*I$31,0) | J35: =SUM(E35:I35)
C36: 2007 Irrevocable Trust For Family of Chris M. Raftis dated March 30,2007 | E36: =IF(H$31>F$9,-F$9*F11,0) | F36: =IF(I$31>G$9,-G$9*G11,0) | G36: =E11*G$31 | H36: =IF(E$45<0,F11*H$31,0) | I36: =IF(F$45<0,G11*I$31,0) | J36: =SUM(E36:I36)
C37: PTI Inc. Seller (Karl Trott) | E37: =IF(H$31>F$9,-F$9*F12,0) | F37: =IF(I$31>G$9,-G$9*G12,0) | G37: =E12*G$31 | H37: =IF(E$45<0,F12*H$31,0) | I37: =IF(F$45<0,G12*I$31,0) | J37: =SUM(E37:I37)
C38: John DeYarman Incentive Units | E38: =IF(H$31>F$9,-F$9*F13,0) | F38: =IF(I$31>G$9,-G$9*G13,0) | H38: =IF(E$45<0,F13*H$31,0) | I38: =IF(F$45<0,G13*I$31,0) | J38: =SUM(E38:I38)
C39: Scott Day Incentive Units | E39: =IF(H$31>F$9,-F$9*F14,0) | F39: =IF(I$31>G$9,-G$9*G14,0) | H39: =IF(E$45<0,F14*H$31,0) | I39: =IF(F$45<0,G14*I$31,0) | J39: =SUM(E39:I39)
C40: 2007 Irrevocable Trust For Family of Chris M. Raftis dated March 30,2007 Incentive Units | E40: =IF(H$31>F$9,-F$9*F15,0) | F40: =IF(I$31>G$9,-G$9*G15,0) | H40: =IF(E$45<0,F15*H$31,0) | I40: =IF(F$45<0,G15*I$31,0) | J40: =SUM(E40:I40)
C41: Kevin Klau | E41: =IF(H$31>F$9,-F$9*F16,0) | F41: =IF(I$31>G$9,-G$9*G16,0) | H41: =IF(E$45<0,F16*H$31,0) | I41: =IF(F$45<0,G16*I$31,0) | J41: =SUM(E41:I41)
C42: Warren Berenis | E42: =IF(H$31>F$9,-F$9*F17,0) | F42: =IF(I$31>G$9,-G$9*G17,0) | H42: =IF(E$45<0,F17*H$31,0) | I42: =IF(F$45<0,G17*I$31,0) | J42: =SUM(E42:I42)
C43: Unallocated | E43: =IF(H$31>F$9,-F$9*F18,0) | F43: =IF(I$31>G$9,-G$9*G18,0) | H43: =IF(E$45<0,F18*H$31,0) | I43: =IF(F$45<0,G18*I$31,0) | J43: =SUM(E43:I43)
C45: TOTAL | E45: =SUM(E35:E44) | F45: =SUM(F35:F44) | G45: =SUM(G35:G44) | H45: =SUM(H35:H44) | I45: =SUM(I35:I44) | J45: =SUM(J35:J44)

Sheet Cap Table (Dec 2025)
B2: Opus Water - Cap Table | K2: Confidential
K3: $'s in USD
B4: Illustrative Equity Value at Exit | D4: ='III. Valuation Summary'!H15
C6: Opus Water Cap Table
D8: Capital | E8: Common Units | F8: Incentive Units | G8: Incentive Units | H8: Total | I8: % | J8: Total | K8: %
D9: Contributed | E9: Exercise prices>>> | F9: 1 | G9: 1.6 | H9: (Basic) | I9: (Basic) | J9: (Fully Diluted) | K9: (Fully Diluted)
C10: XPV Water Fund III Limited Partnership | D10: =12500000+3787879.18 | E10: 14628022 | H10: =E10 | I10: =H10/H$19 | J10: =SUM(E10:G10) | K10: =J10/J$19
C11: 2007 Irrevocable Trust For Family of Chris M. Raftis dated March 30,2007 | D11: =600000+181818.1 | E11: 702145 | H11: =E11 | I11: =H11/H$19 | J11: =SUM(E11:G11) | K11: =J11/J$19
C12: Karl Trott | D12: =100000+30302.72 | E12: 117024 | H12: =E12 | I12: =H12/H$19 | J12: =SUM(E12:G12) | K12: =J12/J$19
C13: John DeYarman Incentive Units | F13: 233333 | G13: 466667 | I13: =H13/H$19 | J13: =SUM(E13:G13) | K13: =J13/J$19
C14: Scott Day Incentive Units | G14: 300000 | I14: =H14/H$19 | J14: =SUM(E14:G14) | K14: =J14/J$19
C15: 2007 Irrevocable Trust For Family of Chris M. Raftis dated March 30,2007 Incentive Units | G15: 110000 | I15: =H15/H$19 | J15: =SUM(E15:G15) | K15: =J15/J$19
C16: Kevin Klau | G16: 110000 | I16: =H16/H$19 | J16: =SUM(E16:G16) | K16: =J16/J$19
C17: Warren Berenis | G17: =150000+25000 | I17: =H17/H$19 | J17: =SUM(E17:G17) | K17: =J17/J$19
C18: Unallocated | G18: =1400000-SUM(F13:G17) | I18: =H18/H$19 | J18: =SUM(E18:G18) | K18: =J18/J$19
C19: Total | E19: =SUM(E10:E18) | F19: =SUM(F10:F18) | G19: =SUM(G10:G18) | H19: =SUM(H10:H18) | I19: =H19/H$19 | J19: =SUM(J10:J18) | K19: =J19/J$19
B21: EQUITY PROCEEDS
E22: Incentive Units | F22: Incentive Units | G22: Common Units | H22: Incentive Units | I22: Incentive Units
E23: =F9 | F23: =G9 | H23: =F9 | I23: =G9
C24: Equity Value | E24: =D4 | F24: =E24 | G24: =F24-E45-F45 | H24: =G24 | I24: =H24
C26: Common Units | E26: =E19 | F26: =E26 | G26: =E26 | H26: =G26 | I26: =H26
C27: Incentive Units ($1.00) | E27: =F19 | F27: =E27 | G27: =IF(E45<0,E27,0) | H27: =G27 | I27: =H27
C28: Incentive Units ($1.60) | E28: =G19 | F28: =E28 | G28: =IF(F45<0,E28,0) | H28: =G28 | I28: =H28
C30: Total Units | E30: =SUM(E26:E29) | F30: =SUM(F26:F29) | G30: =SUM(G26:G29) | H30: =SUM(H26:H29) | I30: =SUM(I26:I29)
C31: Equity Value Per Unit | E31: =E24/E30 | F31: =F24/F30 | G31: =G24/G30 | H31: =H24/H30 | I31: =I24/I30
E33: Options Exercise | G33: Common Units
E34: Incentive Units ($1.00) | F34: Incentive Units ($1.60) | G34: Common Units | H34: Incentive Units ($1.00) | I34: Incentive Units ($1.60) | J34: Proceeds
C35: XPV Water Fund III Limited Partnership | E35: =IF(H$31>F$9,-F$9*F10,0) | F35: =IF(I$31>G$9,-G$9*G10,0) | G35: =E10*G$31 | H35: =IF(E$45<0,F10*H$31,0) | I35: =IF(F$45<0,G10*I$31,0) | J35: =SUM(E35:I35)
C36: 2007 Irrevocable Trust For Family of Chris M. Raftis dated March 30,2007 | E36: =IF(H$31>F$9,-F$9*F11,0) | F36: =IF(I$31>G$9,-G$9*G11,0) | G36: =E11*G$31 | H36: =IF(E$45<0,F11*H$31,0) | I36: =IF(F$45<0,G11*I$31,0) | J36: =SUM(E36:I36)
C37: PTI Inc. Seller (Karl Trott) | E37: =IF(H$31>F$9,-F$9*F12,0) | F37: =IF(I$31>G$9,-G$9*G12,0) | G37: =E12*G$31 | H37: =IF(E$45<0,F12*H$31,0) | I37: =IF(F$45<0,G12*I$31,0) | J37: =SUM(E37:I37)
C38: John DeYarman Incentive Units | E38: =IF(H$31>F$9,-F$9*F13,0) | F38: =IF(I$31>G$9,-G$9*G13,0) | H38: =IF(E$45<0,F13*H$31,0) | I38: =IF(F$45<0,G13*I$31,0) | J38: =SUM(E38:I38)
C39: Scott Day Incentive Units | E39: =IF(H$31>F$9,-F$9*F14,0) | F39: =IF(I$31>G$9,-G$9*G14,0) | H39: =IF(E$45<0,F14*H$31,0) | I39: =IF(F$45<0,G14*I$31,0) | J39: =SUM(E39:I39)
C40: 2007 Irrevocable Trust For Family of Chris M. Raftis dated March 30,2007 Incentive Units | E40: =IF(H$31>F$9,-F$9*F15,0) | F40: =IF(I$31>G$9,-G$9*G15,0) | H40: =IF(E$45<0,F15*H$31,0) | I40: =IF(F$45<0,G15*I$31,0) | J40: =SUM(E40:I40)
C41: Kevin Klau | E41: =IF(H$31>F$9,-F$9*F16,0) | F41: =IF(I$31>G$9,-G$9*G16,0) | H41: =IF(E$45<0,F16*H$31,0) | I41: =IF(F$45<0,G16*I$31,0) | J41: =SUM(E41:I41)
C42: Warren Berenis | E42: =IF(H$31>F$9,-F$9*F17,0) | F42: =IF(I$31>G$9,-G$9*G17,0) | H42: =IF(E$45<0,F17*H$31,0) | I42: =IF(F$45<0,G17*I$31,0) | J42: =SUM(E42:I42)
C43: Unallocated | E43: =IF(H$31>F$9,-F$9*F18,0) | F43: =IF(I$31>G$9,-G$9*G18,0) | H43: =IF(E$45<0,F18*H$31,0) | I43: =IF(F$45<0,G18*I$31,0) | J43: =SUM(E43:I43)
C45: TOTAL | E45: =SUM(E35:E44) | F45: =SUM(F35:F44) | G45: =SUM(G35:G44) | H45: =SUM(H35:H44) | I45: =SUM(I35:I44) | J45: =SUM(J35:J44)

Sheet Cap Table (Dec 2024)
B2: Opus Water - Cap Table | K2: Confidential
K3: $'s in USD
B4: Illustrative Equity Value at Exit | D4: ='III. Valuation Summary'!H15
C6: Opus Water Cap Table
E8: Common Units | F8: Incentive Units | G8: Incentive Units | H8: Total | I8: % | J8: Total | K8: %
E9: Exercise prices>>> | F9: 1 | G9: 1.6 | H9: (Basic) | I9: (Basic) | J9: (Fully Diluted) | K9: (Fully Diluted)
C10: XPV Water Fund III Limited Partnership | E10: 12500000 | H10: =E10 | I10: =H10/H$19 | J10: =SUM(E10:G10) | K10: =J10/J$19
C11: 2007 Irrevocable Trust For Family of Chris M. Raftis dated March 30,2007 | E11: 600000 | H11: =E11 | I11: =H11/H$19 | J11: =SUM(E11:G11) | K11: =J11/J$19
C12: Karl Trott | E12: 100000 | H12: =E12 | I12: =H12/H$19 | J12: =SUM(E12:G12) | K12: =J12/J$19
C13: John DeYarman Incentive Units | F13: 233333 | G13: 466667 | I13: =H13/H$19 | J13: =SUM(E13:G13) | K13: =J13/J$19
C14: Scott Day Incentive Units | G14: 300000 | I14: =H14/H$19 | J14: =SUM(E14:G14) | K14: =J14/J$19
C15: 2007 Irrevocable Trust For Family of Chris M. Raftis dated March 30,2007 Incentive Units | G15: 110000 | I15: =H15/H$19 | J15: =SUM(E15:G15) | K15: =J15/J$19
C16: Kevin Klau | G16: 110000 | I16: =H16/H$19 | J16: =SUM(E16:G16) | K16: =J16/J$19
C17: Warren Berenis | G17: 150000 | I17: =H17/H$19 | J17: =SUM(E17:G17) | K17: =J17/J$19
C18: Unallocated | G18: =1400000-SUM(F13:G17) | I18: =H18/H$19 | J18: =SUM(E18:G18) | K18: =J18/J$19
C19: Total | E19: =SUM(E10:E18) | F19: =SUM(F10:F18) | G19: =SUM(G10:G18) | H19: =SUM(H10:H18) | I19: =H19/H$19 | J19: =SUM(J10:J18) | K19: =J19/J$19
B21: EQUITY PROCEEDS
E22: Incentive Units | F22: Incentive Units | G22: Common Units | H22: Incentive Units | I22: Incentive Units
E23: =F9 | F23: =G9 | H23: =F9 | I23: =G9
C24: Equity Value | E24: =D4 | F24: =E24 | G24: =F24-E45-F45 | H24: =G24 | I24: =H24
C26: Common Units | E26: =E19 | F26: =E26 | G26: =E26 | H26: =G26 | I26: =H26
C27: Incentive Units ($1.00) | E27: =F19 | F27: =E27 | G27: =IF(E45<0,E27,0) | H27: =G27 | I27: =H27
C28: Incentive Units ($1.60) | E28: =G19 | F28: =E28 | G28: =IF(F45<0,E28,0) | H28: =G28 | I28: =H28
C30: Total Units | E30: =SUM(E26:E29) | F30: =SUM(F26:F29) | G30: =SUM(G26:G29) | H30: =SUM(H26:H29) | I30: =SUM(I26:I29)
C31: Equity Value Per Unit | E31: =E24/E30 | F31: =F24/F30 | G31: =G24/G30 | H31: =H24/H30 | I31: =I24/I30
E33: Options Exercise | G33: Common Units
E34: Incentive Units ($1.00) | F34: Incentive Units ($1.60) | G34: Common Units | H34: Incentive Units ($1.00) | I34: Incentive Units ($1.60) | J34: Proceeds
C35: XPV Water Fund III Limited Partnership | E35: =IF(H$31>F$9,-F$9*F10,0) | F35: =IF(I$31>G$9,-G$9*G10,0) | G35: =E10*G$31 | H35: =IF(E$45<0,F10*H$31,0) | I35: =IF(F$45<0,G10*I$31,0) | J35: =SUM(E35:I35)
C36: 2007 Irrevocable Trust For Family of Chris M. Raftis dated March 30,2007 | E36: =IF(H$31>F$9,-F$9*F11,0) | F36: =IF(I$31>G$9,-G$9*G11,0) | G36: =E11*G$31 | H36: =IF(E$45<0,F11*H$31,0) | I36: =IF(F$45<0,G11*I$31,0) | J36: =SUM(E36:I36)
C37: PTI Inc. Seller (Karl Trott) | E37: =IF(H$31>F$9,-F$9*F12,0) | F37: =IF(I$31>G$9,-G$9*G12,0) | G37: =E12*G$31 | H37: =IF(E$45<0,F12*H$31,0) | I37: =IF(F$45<0,G12*I$31,0) | J37: =SUM(E37:I37)
C38: John DeYarman Incentive Units | E38: =IF(H$31>F$9,-F$9*F13,0) | F38: =IF(I$31>G$9,-G$9*G13,0) | H38: =IF(E$45<0,F13*H$31,0) | I38: =IF(F$45<0,G13*I$31,0) | J38: =SUM(E38:I38)
C39: Scott Day Incentive Units | E39: =IF(H$31>F$9,-F$9*F14,0) | F39: =IF(I$31>G$9,-G$9*G14,0) | H39: =IF(E$45<0,F14*H$31,0) | I39: =IF(F$45<0,G14*I$31,0) | J39: =SUM(E39:I39)
C40: 2007 Irrevocable Trust For Family of Chris M. Raftis dated March 30,2007 Incentive Units | E40: =IF(H$31>F$9,-F$9*F15,0) | F40: =IF(I$31>G$9,-G$9*G15,0) | H40: =IF(E$45<0,F15*H$31,0) | I40: =IF(F$45<0,G15*I$31,0) | J40: =SUM(E40:I40)
C41: Kevin Klau | E41: =IF(H$31>F$9,-F$9*F16,0) | F41: =IF(I$31>G$9,-G$9*G16,0) | H41: =IF(E$45<0,F16*H$31,0) | I41: =IF(F$45<0,G16*I$31,0) | J41: =SUM(E41:I41)
C42: Warren Berenis | E42: =IF(H$31>F$9,-F$9*F17,0) | F42: =IF(I$31>G$9,-G$9*G17,0) | H42: =IF(E$45<0,F17*H$31,0) | I42: =IF(F$45<0,G17*I$31,0) | J42: =SUM(E42:I42)
C43: Unallocated | E43: =IF(H$31>F$9,-F$9*F18,0) | F43: =IF(I$31>G$9,-G$9*G18,0) | H43: =IF(E$45<0,F18*H$31,0) | I43: =IF(F$45<0,G18*I$31,0) | J43: =SUM(E43:I43)
C45: TOTAL | E45: =SUM(E35:E44) | F45: =SUM(F35:F44) | G45: =SUM(G35:G44) | H45: =SUM(H35:H44) | I45: =SUM(I35:I44) | J45: =SUM(J35:J44)

Sheet IRR Calculation (Mar 2026)
B1: ='I. Cover Page'!B5
B2: XPVWFII Returns
B3: ='I. Cover Page'!B9 | L3: $USD
C5: Security Type | I5: 45281 | J5: 45982 | K5: =J5 | L5: =B3
B7: Total Investment IRR
B8: Initial Common Equity Investment | D8: Common | I8: -12500000
B9: Common Equity Payout @ Exit | D9: Common | F9: Unrealized Value | L9: ='III. Valuation Summary'!$F$25
B10: Common Shares (Growth Investment) | D10: Common
B11: Founder share purchase | D11: Common
B12: Add-On Investments (Yeary Controls) | D12: Common | F12: Unrealized Value | J12: -3787879.2
B13: Add-On Investments
B14: Add-On Investments
B15: [X] | F15: Realized Value
B16: Blended Cash Flow | I16: =SUM(I8:I15) | J16: =SUM(J8:J15) | K16: =SUM(K8:K15) | L16: =SUM(L8:L15)
B18: Total Investments | F18: =SUM(I16:K16)
B20: Realized Value | F20: =SUMIF($F$8:$F$15,B20,$L$8:$L$15)
B21: Unrealized Value | F21: =SUMIF($F$8:$F$15,B21,$L$8:$L$15)
B22: Total Realized & Unrealized Value | F22: =F20+F21
B24: Realized ROI | F24: =-F20/$F$18
B25: Unrealized ROI | F25: =-F21/$F$18
B26: Realized & Unrealized ROI | F26: =-F22/$F$18
B28: IRR | F28: =IFERROR(XIRR(I16:L16,I5:L5),"NM")

Sheet IRR Calculation (Dec 2025)
B1: ='I. Cover Page'!B5
B2: XPVWFII Returns
B3: 46022 | L3: $USD
C5: Security Type | I5: 45281 | J5: 45982 | K5: =J5 | L5: =B3
B7: Total Investment IRR
B8: Initial Common Equity Investment | D8: Common | I8: -12500000
B9: Common Equity Payout @ Exit | D9: Common | F9: Unrealized Value | L9: ='III. Valuation Summary'!H25
B10: Common Shares (Growth Investment) | D10: Common
B11: Founder share purchase | D11: Common
B12: Add-On Investments (Yeary Controls) | D12: Common | F12: Unrealized Value | J12: -3787879.2
B13: Add-On Investments
B14: Add-On Investments
B15: [X] | F15: Realized Value
B16: Blended Cash Flow | I16: =SUM(I8:I15) | J16: =SUM(J8:J15) | K16: =SUM(K8:K15) | L16: =SUM(L8:L15)
B18: Total Investments | F18: =SUM(I16:K16)
B20: Realized Value | F20: =SUMIF($F$8:$F$15,B20,$L$8:$L$15)
B21: Unrealized Value | F21: =SUMIF($F$8:$F$15,B21,$L$8:$L$15)
B22: Total Realized & Unrealized Value | F22: =F20+F21
B24: Realized ROI | F24: =-F20/$F$18
B25: Unrealized ROI | F25: =-F21/$F$18
B26: Realized & Unrealized ROI | F26: =-F22/$F$18
B28: IRR | F28: =IFERROR(XIRR(I16:L16,I5:L5),"NM")

Sheet IRR Calculation (Dec 2024)
B1: ='I. Cover Page'!B5
B2: XPVWFII Returns
B3: ='I. Cover Page'!B9 | L3: $USD
C5: Security Type | I5: 45283 | J5: =I5 | K5: =J5 | L5: 45657
B7: Total Investment IRR
B8: Initial Common Equity Investment | D8: Common | I8: -12500000
